2021-10-25 14:22:46,978 INFO    MainThread:9668 [internal.py:wandb_internal():86] W&B internal server running at pid: 9668, started at: 2021-10-25 14:22:46.978006
2021-10-25 14:22:46,993 INFO    WriterThread:9668 [datastore.py:open_for_write():77] open: C:\Users\Thishen\Documents\GitHub\crowd-density\wandb\run-20211025_142245-3fylf5jj\run-3fylf5jj.wandb
2021-10-25 14:22:46,993 DEBUG   HandlerThread:9668 [handler.py:handle_request():126] handle_request: check_version
2021-10-25 14:22:46,993 DEBUG   SenderThread:9668 [sender.py:send():185] send: header
2021-10-25 14:22:46,993 DEBUG   SenderThread:9668 [sender.py:send_request():199] send_request: check_version
2021-10-25 14:22:46,993 DEBUG   SenderThread:9668 [sender.py:send():185] send: run
2021-10-25 14:22:47,830 WARNING MainThread:9668 [internal.py:wandb_internal():145] Internal process interrupt: 1
2021-10-25 14:22:48,831 WARNING MainThread:9668 [internal.py:is_dead():364] Internal process exiting, parent pid 7300 disappeared
2021-10-25 14:22:48,831 ERROR   MainThread:9668 [internal.py:wandb_internal():141] Internal process shutdown.
2021-10-25 14:22:49,003 INFO    WriterThread:9668 [datastore.py:close():281] close: C:\Users\Thishen\Documents\GitHub\crowd-density\wandb\run-20211025_142245-3fylf5jj\run-3fylf5jj.wandb
2021-10-25 14:22:49,003 INFO    HandlerThread:9668 [handler.py:finish():683] shutting down handler
2021-10-25 14:22:50,409 ERROR   SenderThread:9668 [retry.py:__call__():126] Retry attempt failed:
Traceback (most recent call last):
  File "C:\Users\Thishen\anaconda3\lib\site-packages\urllib3\connection.py", line 169, in _new_conn
    conn = connection.create_connection(
  File "C:\Users\Thishen\anaconda3\lib\site-packages\urllib3\util\connection.py", line 73, in create_connection
    for res in socket.getaddrinfo(host, port, family, socket.SOCK_STREAM):
  File "C:\Users\Thishen\anaconda3\lib\socket.py", line 918, in getaddrinfo
    for res in _socket.getaddrinfo(host, port, family, type, proto, flags):
socket.gaierror: [Errno 11001] getaddrinfo failed

During handling of the above exception, another exception occurred:

Traceback (most recent call last):
  File "C:\Users\Thishen\anaconda3\lib\site-packages\urllib3\connectionpool.py", line 699, in urlopen
    httplib_response = self._make_request(
  File "C:\Users\Thishen\anaconda3\lib\site-packages\urllib3\connectionpool.py", line 382, in _make_request
    self._validate_conn(conn)
  File "C:\Users\Thishen\anaconda3\lib\site-packages\urllib3\connectionpool.py", line 1010, in _validate_conn
    conn.connect()
  File "C:\Users\Thishen\anaconda3\lib\site-packages\urllib3\connection.py", line 353, in connect
    conn = self._new_conn()
  File "C:\Users\Thishen\anaconda3\lib\site-packages\urllib3\connection.py", line 181, in _new_conn
    raise NewConnectionError(
urllib3.exceptions.NewConnectionError: <urllib3.connection.HTTPSConnection object at 0x00000268A0845400>: Failed to establish a new connection: [Errno 11001] getaddrinfo failed

During handling of the above exception, another exception occurred:

Traceback (most recent call last):
  File "C:\Users\Thishen\anaconda3\lib\site-packages\requests\adapters.py", line 439, in send
    resp = conn.urlopen(
  File "C:\Users\Thishen\anaconda3\lib\site-packages\urllib3\connectionpool.py", line 755, in urlopen
    retries = retries.increment(
  File "C:\Users\Thishen\anaconda3\lib\site-packages\urllib3\util\retry.py", line 574, in increment
    raise MaxRetryError(_pool, url, error or ResponseError(cause))
urllib3.exceptions.MaxRetryError: HTTPSConnectionPool(host='api.wandb.ai', port=443): Max retries exceeded with url: /graphql (Caused by NewConnectionError('<urllib3.connection.HTTPSConnection object at 0x00000268A0845400>: Failed to establish a new connection: [Errno 11001] getaddrinfo failed'))

During handling of the above exception, another exception occurred:

Traceback (most recent call last):
  File "C:\Users\Thishen\anaconda3\lib\site-packages\wandb\sdk\lib\retry.py", line 102, in __call__
    result = self._call_fn(*args, **kwargs)
  File "C:\Users\Thishen\anaconda3\lib\site-packages\wandb\sdk\internal\internal_api.py", line 132, in execute
    return self.client.execute(*args, **kwargs)
  File "C:\Users\Thishen\anaconda3\lib\site-packages\wandb\vendor\gql-0.2.0\gql\client.py", line 52, in execute
    result = self._get_result(document, *args, **kwargs)
  File "C:\Users\Thishen\anaconda3\lib\site-packages\wandb\vendor\gql-0.2.0\gql\client.py", line 60, in _get_result
    return self.transport.execute(document, *args, **kwargs)
  File "C:\Users\Thishen\anaconda3\lib\site-packages\wandb\vendor\gql-0.2.0\gql\transport\requests.py", line 38, in execute
    request = requests.post(self.url, **post_args)
  File "C:\Users\Thishen\anaconda3\lib\site-packages\requests\api.py", line 119, in post
    return request('post', url, data=data, json=json, **kwargs)
  File "C:\Users\Thishen\anaconda3\lib\site-packages\requests\api.py", line 61, in request
    return session.request(method=method, url=url, **kwargs)
  File "C:\Users\Thishen\anaconda3\lib\site-packages\requests\sessions.py", line 542, in request
    resp = self.send(prep, **send_kwargs)
  File "C:\Users\Thishen\anaconda3\lib\site-packages\requests\sessions.py", line 655, in send
    r = adapter.send(request, **kwargs)
  File "C:\Users\Thishen\anaconda3\lib\site-packages\requests\adapters.py", line 516, in send
    raise ConnectionError(e, request=request)
requests.exceptions.ConnectionError: HTTPSConnectionPool(host='api.wandb.ai', port=443): Max retries exceeded with url: /graphql (Caused by NewConnectionError('<urllib3.connection.HTTPSConnection object at 0x00000268A0845400>: Failed to establish a new connection: [Errno 11001] getaddrinfo failed'))
2021-10-25 14:23:04,357 INFO    SenderThread:9668 [dir_watcher.py:__init__():169] watching files in: C:\Users\Thishen\Documents\GitHub\crowd-density\wandb\run-20211025_142245-3fylf5jj\files
2021-10-25 14:23:04,357 INFO    SenderThread:9668 [sender.py:_start_run_threads():746] run started: 3fylf5jj with start time 1635164565
2021-10-25 14:23:04,357 INFO    SenderThread:9668 [sender.py:finish():986] shutting down sender
2021-10-25 14:23:04,357 INFO    SenderThread:9668 [dir_watcher.py:finish():283] shutting down directory watcher
2021-10-25 14:23:05,373 INFO    SenderThread:9668 [dir_watcher.py:finish():313] scan: C:\Users\Thishen\Documents\GitHub\crowd-density\wandb\run-20211025_142245-3fylf5jj\files
2021-10-25 14:23:05,373 INFO    SenderThread:9668 [dir_watcher.py:finish():327] scan save: C:\Users\Thishen\Documents\GitHub\crowd-density\wandb\run-20211025_142245-3fylf5jj\files\config.yaml config.yaml
2021-10-25 14:23:05,373 INFO    SenderThread:9668 [file_pusher.py:finish():177] shutting down file pusher
2021-10-25 14:23:05,373 INFO    SenderThread:9668 [file_pusher.py:join():182] waiting for file pusher
2021-10-25 14:23:06,466 INFO    Thread-14 :9668 [upload_job.py:push():137] Uploaded file C:\Users\Thishen\Documents\GitHub\crowd-density\wandb\run-20211025_142245-3fylf5jj\files\config.yaml
2021-10-25 14:23:07,217 INFO    MainThread:9668 [internal.py:handle_exit():76] Internal process exited
